Workbook
Name _Hlk32994821: 'Data Entry'!$A$27

Sheet Data Entry
A2: Master Job Number | C2: {{Job Number}} | E2: Total Lot Qty | F2: {{Total Quantity}} | G2: Date Inspected | I2: {{Date}} | K2: Top Level Engineering Specification | M2: CMD C.L.00.00.C aprevo LLIF Rev21
A3: Part Number | E3: Traveler # | G3: Customer Lot # | I3: Notes (NCR, etc)
A4: {{Item 1}} | E4: {{Traceler Number}} | G4: {{Lot Number}} | I4: N/A
A5: {{Item 2}} | E5: {{Traceler Number}} | G5: {{Lot Number}} | I5: N/A
A6: {{Item 3}} | E6: {{Traceler Number}} | G6: {{Lot Number}} | I6: N/A
A7: {{Item 4}} | E7: {{Traceler Number}} | G7: {{Lot Number}} | I7: N/A
A8: {{Item 5}} | E8: {{Traceler Number}} | G8: {{Lot Number}} | I8: N/A
A9: {{Item 6}} | E9: {{Traceler Number}} | G9: {{Lot Number}} | I9: N/A
A10: {{Item 7}} | E10: {{Traceler Number}} | G10: {{Lot Number}} | I10: N/A
A11: {{Item 8}} | E11: {{Traceler Number}} | G11: {{Lot Number}} | I11: N/A
A12: {{Item 9}} | E12: {{Traceler Number}} | G12: {{Lot Number}} | I12: N/A
A14: Notes: * Final Process Tolerances are 0.001" (0.03mm) tighter on each side than the drawing to compensate for any measurement variation during future measurements. * Use Page One for data entry. Go to the Page Two 'Conv Tables' to enter the nominal measurement dimension per CMD provided Form-019 * Record the full Part Numbers below such as C.L34.01.C, C.L45.02.C & C.L51.03.C.
A15: Line # | B15: Part Number | C15: Dim C Implant Height (mm) | E15: Dim B AP Depth (mm) | G15: Dim A ML Width (mm)
A16: 1
A17: 2
A18: 3
A19: 4
A20: 5
A21: 6
A22: 7
A23: 8
A24: 9
A28: Delta-to-Target "Spec" Limits (+/- mm) | C28: 0.5 | E28: 0.5 | G28: 0.5
A29: Line # | B29: =B15 -> Part Number | C29: =C15 -> Dim C Implant Height (mm) | E29: =E15 -> Dim B AP Depth (mm) | G29: =G15 -> Dim A ML Width (mm)
A30: ='Data Entry'!A16 -> 1 | B30: ='Data Entry'!B16 -> 0 | C30: =ROUND(-VLOOKUP($B30,'Conv Tables'!$B$2:$E$23,2,FALSE)+C16,2) -> #N/A | E30: =ROUND(-VLOOKUP($B30,'Conv Tables'!$B$2:$E$23,3,FALSE)+E16,2) -> #N/A | G30: =ROUND(-VLOOKUP($B30,'Conv Tables'!$B$2:$E$23,4,FALSE)+G16,2) -> #N/A
A31: ='Data Entry'!A17 -> 2 | B31: ='Data Entry'!B17 -> 0 | C31: =ROUND(-VLOOKUP($B31,'Conv Tables'!$B$2:$E$23,2,FALSE)+C17,2) -> #N/A | E31: =ROUND(-VLOOKUP($B31,'Conv Tables'!$B$2:$E$23,3,FALSE)+E17,2) -> #N/A | G31: =ROUND(-VLOOKUP($B31,'Conv Tables'!$B$2:$E$23,4,FALSE)+G17,2) -> #N/A
A32: ='Data Entry'!A18 -> 3 | B32: ='Data Entry'!B18 -> 0 | C32: =ROUND(-VLOOKUP($B32,'Conv Tables'!$B$2:$E$23,2,FALSE)+C18,2) -> #N/A | E32: =ROUND(-VLOOKUP($B32,'Conv Tables'!$B$2:$E$23,3,FALSE)+E18,2) -> #N/A | G32: =ROUND(-VLOOKUP($B32,'Conv Tables'!$B$2:$E$23,4,FALSE)+G18,2) -> #N/A
A33: ='Data Entry'!A19 -> 4 | B33: ='Data Entry'!B19 -> 0 | C33: =ROUND(-VLOOKUP($B33,'Conv Tables'!$B$2:$E$23,2,FALSE)+C19,2) -> #N/A | E33: =ROUND(-VLOOKUP($B33,'Conv Tables'!$B$2:$E$23,3,FALSE)+E19,2) -> #N/A | G33: =ROUND(-VLOOKUP($B33,'Conv Tables'!$B$2:$E$23,4,FALSE)+G19,2) -> #N/A
A34: ='Data Entry'!A20 -> 5 | B34: ='Data Entry'!B20 -> 0 | C34: =ROUND(-VLOOKUP($B34,'Conv Tables'!$B$2:$E$23,2,FALSE)+C20,2) -> #N/A | E34: =ROUND(-VLOOKUP($B34,'Conv Tables'!$B$2:$E$23,3,FALSE)+E20,2) -> #N/A | G34: =ROUND(-VLOOKUP($B34,'Conv Tables'!$B$2:$E$23,4,FALSE)+G20,2) -> #N/A
A35: ='Data Entry'!A21 -> 6 | B35: ='Data Entry'!B21 -> 0 | C35: =ROUND(-VLOOKUP($B35,'Conv Tables'!$B$2:$E$23,2,FALSE)+C21,2) -> #N/A | E35: =ROUND(-VLOOKUP($B35,'Conv Tables'!$B$2:$E$23,3,FALSE)+E21,2) -> #N/A | G35: =ROUND(-VLOOKUP($B35,'Conv Tables'!$B$2:$E$23,4,FALSE)+G21,2) -> #N/A
A36: ='Data Entry'!A22 -> 7 | B36: ='Data Entry'!B22 -> 0 | C36: =ROUND(-VLOOKUP($B36,'Conv Tables'!$B$2:$E$23,2,FALSE)+C22,2) -> #N/A | E36: =ROUND(-VLOOKUP($B36,'Conv Tables'!$B$2:$E$23,3,FALSE)+E22,2) -> #N/A | G36: =ROUND(-VLOOKUP($B36,'Conv Tables'!$B$2:$E$23,4,FALSE)+G22,2) -> #N/A
A37: ='Data Entry'!A23 -> 8 | B37: ='Data Entry'!B23 -> 0 | C37: =ROUND(-VLOOKUP($B37,'Conv Tables'!$B$2:$E$23,2,FALSE)+C23,2) -> #N/A | E37: =ROUND(-VLOOKUP($B37,'Conv Tables'!$B$2:$E$23,3,FALSE)+E23,2) -> #N/A | G37: =ROUND(-VLOOKUP($B37,'Conv Tables'!$B$2:$E$23,4,FALSE)+G23,2) -> #N/A
A38: ='Data Entry'!A24 -> 9 | B38: ='Data Entry'!B24 -> 0 | C38: =ROUND(-VLOOKUP($B38,'Conv Tables'!$B$2:$E$23,2,FALSE)+C24,2) -> #N/A | E38: =ROUND(-VLOOKUP($B38,'Conv Tables'!$B$2:$E$23,3,FALSE)+E24,2) -> #N/A | G38: =ROUND(-VLOOKUP($B38,'Conv Tables'!$B$2:$E$23,4,FALSE)+G24,2) -> #N/A
A39: _________________________________________________________________________________________
A40: Inspected by:
A42: Form/Template Revision History:
A43: Rev | B43: DCO # | C43: Effective Date | E43: Description of Change
A44: M | B44: 25-112 | C44: 45915 | E44: Parameterize form to auto-populate Job number, Part number and quantity
A45: L | B45: 25-056 | C45: 45799 | E45: Update to drawing Rev 21, removal of the second signature, removal of non-critical dimensions, removal of the warning limits
A46: K | B46: 25-012 | C46: 45688 | E46: Update to drawing Rev 20 (no inspection changes).
...

Sheet Conv Tables
B2: Part # | C2: Dim C Implant Height | D2: Dim B AP Depth | E2: Dim A ML Width
B3: C.L12.01.C
B4: C.L12.02.C
B5: C.L12.03.C
B6: C.L23.01.C
B7: C.L23.02.C
B8: C.L23.03.C
B9: C.L34.01.C
B10: C.L34.02.C
B11: C.L34.03.C
B12: C.L45.01.C
B13: C.L45.02.C
B14: C.L45.03.C
... B23: C.L61.03.C
